# Promise

> JS에서 제공하는 비동기를 간편하게 처리할 수 있도록 도와주는 Object이다.
>
> 정해진 장시간의 기능을 수행한 후 정상적으로 기능이 실행됐다면, 성공의 메시지와 함께 처리된 결과값을 전달해준다.
>
> 만약, 기능을 수행하다가 예외가 발생했다면, 에러를 전달해준다.



```js
// Promise is a JavaScript object for asynchronous operation.

// State : pending -> fulfilled or rejected
// 상태는 promise가 만들어지고 지정한 operation을 수행중일 때 pending상태가 된다.
// operation을 성공적으로 끝내면 fulfilled상태가 된다. 아니면 파일을 찾을 수가 없거나 네트워크에 문제가 생기면 rejected상태가 된다.

// Producer vs Consumer
// 원하는 기능을 수행해서 해당하는 데이터를 만들어내는 producer. 원하는 데이터를 소비하는 consumer로 나누어진다.

// 1. Producer
// when new Promise is created, the executor runs automatically.
const promise = new Promise((resolve, reject) => {
    // doing some heavy works (network, read files)
    // 네트워크에서 데이터를 받아오거나, 파일에서 큰 데이터를 읽어오는 과정은 시간이 오래 걸린다.
    // 이러한 일들을 동기적으로 처리하게 되면, 이를 처리하는 동안 다음Line의 코드가 실행되지 않기 때문에,
    // 시간이 걸리는 일들은 promise를 만들어서 비동기적으로 처리하는 것이 좋다.
    console.log('doing something...!')
    setTimeout(() => {
        resolve('Steven');
    }, 2000);
});


// 2. Consumer : then, catch, finally
promise
    .then((value) => {
    console.log(value);
});
// Steven
// then은 promise가 정상적으로 실행되고 마지막으로 resolve라는 콜백함수를 통해서 값을 전달한다.

const promise = new Promise((resolve, reject) => {
    console.log('doing something...!')
    setTimeout(() => {
        // resolve('Steven');
        reject(new Error('no network'));
    }, 2000);
});
// Uncaught (in promise) Error: no network at ....
// catch로 에러를 잡아줘야 Uncaught에러가 뜨지 않는다.

promise
    .then(value => {
    console.log(value);
})
    .catch(error => {
    console.log(error);
})
    .finally(()=> {
    console.log('finally')
})
// Error: no network at ....
// finally()는 성공 실패와 상관없이 마지막에 무조건 호출된다.


// 3. Promise chaining
const fetchNumber = new Promise((resolve, reject) => {
    setTimeout(() => resolve(1), 1000);
});

fetchNumber
    .then(num => num * 2)
    .then(num => num * 3)
    .then(num => {
    return new Promise((resolve, reject) => {
        setTimeout(() => resolve(num -1), 1000);
    });
})
    .then(num => console.log(num));

// 4. Error Handling
const getHen = () => new Promise((resolve, reject) => {
    setTimeout(() => resolve("hen"), 1000);
});

const getEgg = hen => new Promise((resolve, reject) => {
    setTimeout(()=> resolve(`${hen} => "egg"`), 1000);
    // setTimeout(()=> reject(new Error(`${hen} => "egg"`)), 1000);
});

const cook = egg => new Promise((resolve, reject) => {
    setTimeout(() => resolve(`${egg} => "fried egg"`), 1000);
});

getHen() //
    .then(hen => getEgg(hen))
    .then(egg => cook(egg))
    //.then(cook) 받아오는 벨류가 하나라면, 이런식으로 생략해서 사용이 가능하다.
    .then(meal => console.log(meal));
// "hen" => "egg" => "fried egg"

// getEgg함수가 reject일 때 아래처럼 사용하면 에러도 잡을 수 있다.
getHen() //
    .then(getEgg)
    .catch(error=>{ return "bread"; })
    .then(cook)
    .then(console.log);
// "bread" => "fried egg"


```

